[2023-10-28T20:37:50.179+0000] {taskinstance.py:1159} INFO - Dependencies all met for dep_context=non-requeueable deps ti=<TaskInstance: etl_reddit_pipeline.reddit_extraction manual__2023-10-28T20:37:48.689328+00:00 [queued]>
[2023-10-28T20:37:50.183+0000] {taskinstance.py:1159} INFO - Dependencies all met for dep_context=requeueable deps ti=<TaskInstance: etl_reddit_pipeline.reddit_extraction manual__2023-10-28T20:37:48.689328+00:00 [queued]>
[2023-10-28T20:37:50.184+0000] {taskinstance.py:1361} INFO - Starting attempt 1 of 1
[2023-10-28T20:37:50.190+0000] {taskinstance.py:1382} INFO - Executing <Task(PythonOperator): reddit_extraction> on 2023-10-28 20:37:48.689328+00:00
[2023-10-28T20:37:50.196+0000] {standard_task_runner.py:57} INFO - Started process 415 to run task
[2023-10-28T20:37:50.200+0000] {standard_task_runner.py:84} INFO - Running: ['airflow', 'tasks', 'run', 'etl_reddit_pipeline', 'reddit_extraction', 'manual__2023-10-28T20:37:48.689328+00:00', '--job-id', '7', '--raw', '--subdir', 'DAGS_FOLDER/reddit_dag.py', '--cfg-path', '/tmp/tmpvz_wnhh8']
[2023-10-28T20:37:50.208+0000] {standard_task_runner.py:85} INFO - Job 7: Subtask reddit_extraction
[2023-10-28T20:37:50.289+0000] {task_command.py:416} INFO - Running <TaskInstance: etl_reddit_pipeline.reddit_extraction manual__2023-10-28T20:37:48.689328+00:00 [running]> on host 2c5944612ac4
[2023-10-28T20:37:50.385+0000] {taskinstance.py:1662} INFO - Exporting env vars: AIRFLOW_CTX_DAG_OWNER='httrinh' AIRFLOW_CTX_DAG_ID='etl_reddit_pipeline' AIRFLOW_CTX_TASK_ID='reddit_extraction' AIRFLOW_CTX_EXECUTION_DATE='2023-10-28T20:37:48.689328+00:00' AIRFLOW_CTX_TRY_NUMBER='1' AIRFLOW_CTX_DAG_RUN_ID='manual__2023-10-28T20:37:48.689328+00:00'
[2023-10-28T20:37:50.392+0000] {logging_mixin.py:151} INFO - Connect to Reddit!
[2023-10-28T20:37:50.996+0000] {taskinstance.py:1937} ERROR - Task failed with exception
Traceback (most recent call last):
  File "/home/airflow/.local/lib/python3.9/site-packages/airflow/operators/python.py", line 192, in execute
    return_value = self.execute_callable()
  File "/home/airflow/.local/lib/python3.9/site-packages/airflow/operators/python.py", line 209, in execute_callable
    return self.python_callable(*self.op_args, **self.op_kwargs)
  File "/opt/airflow/pipelines/reddit_pipeline.py", line 15, in reddit_pipeline
    load_data_to_csv(post_df,filepath)
  File "/opt/airflow/etls/reddit_etl.py", line 42, in load_data_to_csv
    data.to_csv(path,index=False)
  File "/home/airflow/.local/lib/python3.9/site-packages/pandas/core/generic.py", line 3902, in to_csv
    return DataFrameRenderer(formatter).to_csv(
  File "/home/airflow/.local/lib/python3.9/site-packages/pandas/io/formats/format.py", line 1152, in to_csv
    csv_formatter.save()
  File "/home/airflow/.local/lib/python3.9/site-packages/pandas/io/formats/csvs.py", line 247, in save
    with get_handle(
  File "/home/airflow/.local/lib/python3.9/site-packages/pandas/io/common.py", line 739, in get_handle
    check_parent_directory(str(handle))
  File "/home/airflow/.local/lib/python3.9/site-packages/pandas/io/common.py", line 604, in check_parent_directory
    raise OSError(rf"Cannot save file into a non-existent directory: '{parent}'")
OSError: Cannot save file into a non-existent directory: '/opt/airflow/data/output'
[2023-10-28T20:37:51.031+0000] {taskinstance.py:1400} INFO - Marking task as FAILED. dag_id=etl_reddit_pipeline, task_id=reddit_extraction, execution_date=20231028T203748, start_date=20231028T203750, end_date=20231028T203751
[2023-10-28T20:37:51.044+0000] {standard_task_runner.py:104} ERROR - Failed to execute job 7 for task reddit_extraction (Cannot save file into a non-existent directory: '/opt/airflow/data/output'; 415)
[2023-10-28T20:37:51.095+0000] {local_task_job_runner.py:228} INFO - Task exited with return code 1
[2023-10-28T20:37:51.108+0000] {taskinstance.py:2778} INFO - 0 downstream tasks scheduled from follow-on schedule check
