[2023-10-29T00:11:34.316+0000] {taskinstance.py:1159} INFO - Dependencies all met for dep_context=non-requeueable deps ti=<TaskInstance: etl_reddit_pipeline.reddit_extraction manual__2023-10-29T00:11:33.050448+00:00 [queued]>
[2023-10-29T00:11:34.320+0000] {taskinstance.py:1159} INFO - Dependencies all met for dep_context=requeueable deps ti=<TaskInstance: etl_reddit_pipeline.reddit_extraction manual__2023-10-29T00:11:33.050448+00:00 [queued]>
[2023-10-29T00:11:34.321+0000] {taskinstance.py:1361} INFO - Starting attempt 1 of 1
[2023-10-29T00:11:34.327+0000] {taskinstance.py:1382} INFO - Executing <Task(PythonOperator): reddit_extraction> on 2023-10-29 00:11:33.050448+00:00
[2023-10-29T00:11:34.332+0000] {standard_task_runner.py:57} INFO - Started process 435 to run task
[2023-10-29T00:11:34.341+0000] {standard_task_runner.py:84} INFO - Running: ['airflow', 'tasks', 'run', 'etl_reddit_pipeline', 'reddit_extraction', 'manual__2023-10-29T00:11:33.050448+00:00', '--job-id', '10', '--raw', '--subdir', 'DAGS_FOLDER/reddit_dag.py', '--cfg-path', '/tmp/tmp0aqcl1lx']
[2023-10-29T00:11:34.347+0000] {standard_task_runner.py:85} INFO - Job 10: Subtask reddit_extraction
[2023-10-29T00:11:34.400+0000] {task_command.py:416} INFO - Running <TaskInstance: etl_reddit_pipeline.reddit_extraction manual__2023-10-29T00:11:33.050448+00:00 [running]> on host 2c5944612ac4
[2023-10-29T00:11:34.458+0000] {taskinstance.py:1662} INFO - Exporting env vars: AIRFLOW_CTX_DAG_OWNER='httrinh' AIRFLOW_CTX_DAG_ID='etl_reddit_pipeline' AIRFLOW_CTX_TASK_ID='reddit_extraction' AIRFLOW_CTX_EXECUTION_DATE='2023-10-29T00:11:33.050448+00:00' AIRFLOW_CTX_TRY_NUMBER='1' AIRFLOW_CTX_DAG_RUN_ID='manual__2023-10-29T00:11:33.050448+00:00'
[2023-10-29T00:11:34.461+0000] {logging_mixin.py:151} INFO - Connect to Reddit!
[2023-10-29T00:11:35.032+0000] {taskinstance.py:1937} ERROR - Task failed with exception
Traceback (most recent call last):
  File "/home/airflow/.local/lib/python3.9/site-packages/pandas/core/indexes/base.py", line 3790, in get_loc
    return self._engine.get_loc(casted_key)
  File "index.pyx", line 152, in pandas._libs.index.IndexEngine.get_loc
  File "index.pyx", line 181, in pandas._libs.index.IndexEngine.get_loc
  File "pandas/_libs/hashtable_class_helper.pxi", line 7080, in pandas._libs.hashtable.PyObjectHashTable.get_item
  File "pandas/_libs/hashtable_class_helper.pxi", line 7088, in pandas._libs.hashtable.PyObjectHashTable.get_item
KeyError: 'selftext'

The above exception was the direct cause of the following exception:

Traceback (most recent call last):
  File "/home/airflow/.local/lib/python3.9/site-packages/airflow/operators/python.py", line 192, in execute
    return_value = self.execute_callable()
  File "/home/airflow/.local/lib/python3.9/site-packages/airflow/operators/python.py", line 209, in execute_callable
    return self.python_callable(*self.op_args, **self.op_kwargs)
  File "/opt/airflow/pipelines/reddit_pipeline.py", line 12, in reddit_pipeline
    post_df = transform_data(post_df)
  File "/opt/airflow/etls/reddit_etl.py", line 43, in transform_data
    post_df['selftext']
  File "/home/airflow/.local/lib/python3.9/site-packages/pandas/core/frame.py", line 3896, in __getitem__
    indexer = self.columns.get_loc(key)
  File "/home/airflow/.local/lib/python3.9/site-packages/pandas/core/indexes/base.py", line 3797, in get_loc
    raise KeyError(key) from err
KeyError: 'selftext'
[2023-10-29T00:11:35.066+0000] {taskinstance.py:1400} INFO - Marking task as FAILED. dag_id=etl_reddit_pipeline, task_id=reddit_extraction, execution_date=20231029T001133, start_date=20231029T001134, end_date=20231029T001135
[2023-10-29T00:11:35.075+0000] {standard_task_runner.py:104} ERROR - Failed to execute job 10 for task reddit_extraction ('selftext'; 435)
[2023-10-29T00:11:35.098+0000] {local_task_job_runner.py:228} INFO - Task exited with return code 1
[2023-10-29T00:11:35.113+0000] {taskinstance.py:2778} INFO - 0 downstream tasks scheduled from follow-on schedule check
